<?xml version='1.0'?>
<robot name="mybot" xmlns:xacro="http://www.ros.org/wiki/xacro">

	<!-- Put here the robot properties common to the model -->
	<xacro:include filename="$(find mybot_description)/urdf/mybot.gazebo" />
	<xacro:include filename="$(find mybot_description)/urdf/materials.xacro" />
	<xacro:include filename="$(find mybot_description)/urdf/macros.xacro" />

	<xacro:property name="PI" value="3.1415926535897931"/>

	<xacro:property name="chassisHeight" value="0.1"/>
	<xacro:property name="chassisLength" value="0.4"/>
	<xacro:property name="chassisWidth" value="0.2"/>
	<xacro:property name="chassisMass" value="50.0"/>

	<xacro:property name="casterRadius" value="0.08"/>
	<xacro:property name="casterMass" value="5.0"/>

	<xacro:property name="wheelWidth" value="0.05"/>
	<xacro:property name="wheelRadius" value="0.1"/>
	<xacro:property name="wheelPos" value="0.2"/>
	<xacro:property name="wheelMass" value="5.0"/>

	<xacro:property name="cameraSize" value="0.05"/>
	<xacro:property name="cameraMass" value="0.1"/>
	<!-- End of common prperties description -->
<!--	<link name="footprint">-->
<!--	<inertial>-->
<!--		<inertia name="baseFrameInertia">-->
<!--			ixx="0.0" ixy="0.0" ixz="0.0"-->
<!--			iyy="0.0" iyz="0.0"-->
<!--			izz="0.0"/>-->
<!--		</inertia>-->
<!--	</inertial>-->
<!--	</link>-->

<!--	<joint name="base_joint" type="fixed">-->
<!--		<parent link="footprint"/>-->
<!--		<child link="chassis"/>-->
<!--	</joint>-->


	<link name='chassis'>
		<pose>0 0 0.1 0 0 0</pose>
<!--		Box of chassis properties-->
		<collision name="chassisCollision">
			<origin xyz="0 0 ${wheelRadius}" rpy="0 0 0"/>
			<geometry>
				<box size="${chassisLength} ${chassisWidth} ${chassisHeight}"/>
			</geometry>
		</collision>
		<visual name ="chassisVisual">
			<origin xyz="0 0 ${wheelRadius}" rpy="0 0 0"/>
			<geometry>
				<box size="${chassisLength} ${chassisWidth} ${chassisHeight}"/>
			</geometry>
			<material name="orange"/>
		</visual>
		<inertial name="chassisInertia">
			<origin xyz="0 0 ${wheelRadius}" rpy="0 0 0"/>
			<mass value="${chassisMass}"/>
			<xacro:box_inertia m="${chassisMass}" x="${chassisLength}" y="${chassisWidth}" z="${chassisHeight}"/>
		</inertial>

		<collision name="casterCollision">
			<origin xyz="-0.2 0 -0.05" rpy=" 0 0 0"/>
			<geometry>
				<sphere radius="${casterRadius}"/>
			</geometry>
			<surface>
				<friction>
					<ode>
						<mu>0</mu>
						<mu2>0</mu2>
						<slip1>1.0</slip1>
						<slip2>1.0</slip2>
					</ode>
				</friction>
			</surface>
		</collision>
		<visual name="casterVisual">
			<origin xyz="-0.2 0 -0.05" rpy=" 0 0 0"/>
			<geometry>
				<sphere radius="${casterRadius}"/>
			</geometry>
		</visual>

	</link>

	<link name="left_wheel">
		<!--origin xyz="0.1 0.13 0.1" rpy="0 1.5707 1.5707"/-->
		<collision name="collisionLWheel">
			<origin xyz="0 0 0" rpy="0 1.5707 1.5707"/>
			<geometry>
				<cylinder radius="${wheelRadius}" length="${wheelWidth}"/>
			</geometry>
		</collision>
		<visual name="visualLWheel">
			<origin xyz="0 0 0" rpy="0 1.5707 1.5707"/>
			<geometry>
				<cylinder radius="${wheelRadius}" length="${wheelWidth}"/>
			</geometry>
		</visual>
		<inertial>
			<origin xyz="0 0 0" rpy="0 1.5707 1.5707"/>
			<mass value="${wheelMass}"/>
			<xacro:cylinder_inertia m="${wheelMass}" r="${wheelRadius}" h="${wheelWidth}"/>
			<!--			ixx="${wheelMass*(3*wheelRadius*wheelRadius+wheelWidth*wheelWidth)/12}"-->
<!--			<inertia-->
<!--					ixx="${wheelMass*(3*wheelRadius*wheelRadius+wheelWidth*wheelWidth)/12}"-->
<!--					ixy="0.0"-->
<!--					iyy="${wheelMass*(3*wheelRadius*wheelRadius+wheelWidth*wheelWidth)/12}"-->
<!--					ixz="0.0"-->
<!--					izz="wheelMass*wheelRadius*wheelRadius/2.0"-->
<!--					iyz="0.0"-->
<!--			/>-->
		</inertial>
	</link>

	<link name="right_wheel">
		<!--origin xyz="0.1 -0.13 0.1" rpy="0 1.5707 1.5707"/-->
		<collision name="collisionRWheel">
			<origin xyz="0 0 0" rpy="0 1.5707 1.5707"/>
			<geometry>
				<cylinder radius="${wheelRadius}" length="${wheelWidth}"/>
			</geometry>
		</collision>
		<visual name="visualRWheel">
			<origin xyz="0 0 0" rpy="0 1.5707 1.5707"/>
			<geometry>
				<cylinder radius="${wheelRadius}" length="${wheelWidth}"/>
			</geometry>
		</visual>
		<inertial>
			<origin xyz="0 0 0" rpy="0 1.5707 1.5707"/>
			<mass value="${wheelMass}"/>
			<xacro:cylinder_inertia m="${wheelMass}" r="${wheelRadius}" h="${wheelWidth}"/>
<!--		<inertia-->
<!--				ixx="${wheelMass*(3*wheelRadius*wheelRadius+wheelWidth*wheelWidth)/12}"-->
<!--				ixy="0.0"-->
<!--				iyy="${wheelMass*(3*wheelRadius*wheelRadius+wheelWidth*wheelWidth)/12}"-->
<!--				ixz="0.0"-->
<!--				izz="wheelMass*wheelRadius*wheelRadius/2.0"-->
<!--				iyz="0.0"-->
<!--		/>-->
		</inertial>
	</link>


	<joint type="continuous" name="left_wheel_hinge">
		<origin xyz="0.1 0.15 0" rpy="0 0 0"/>
		<child link="left_wheel"/>
		<parent link="chassis"/>
		<axis xyz="0 1 0" rpy="0 0 0"/>
		<limit effort="100" velocity="100"/>
		<joint_properties damping="0.0" friction="0.0"/>
	</joint>

	<joint type="continuous" name="right_wheel_hinge">
		<origin xyz="0.1 -0.15 0" rpy="0 0 0"/>
		<child link="right_wheel"/>
		<parent link="chassis"/>
		<axis xyz="0 1 0" rpy="0 0 0"/>
		<limit effort="100" velocity="100"/>
		<joint_properties damping="0.0" friction="0.0"/>
	</joint>

</robot>